Workbook

Sheet How to use
A1: Swansura keyword research — product pages
A2: Built 18 Oct 2026 from "Swansura_Vilvah_Deyga_Fragrance_Data_Sheet" (546 products: 159 Vilvah & Deyga, 387 fragrance). Keywords are generated from each product name plus real Google UK autocomplete suggestions (google.co.uk, en-GB, collected 18 Oct 2026).
A4: How to add search volumes (Semrush)
A5: 1. Open the "Semrush Batches" tab. Each column is one batch of up to 100 keywords, in priority order (Tier 1 first).
A6: 2. In Semrush go to Keyword Overview, set the database to United Kingdom, paste one batch and click Analyze.
A7: 3. Export the results (Excel/CSV), then paste the export INCLUDING its header row into the "Semrush Data" tab, starting at cell A1. Add later batches below the previous ones (skip their header rows).
A8: 4. Volume, Keyword Difficulty, CPC and Intent fill in automatically on "Products" and "Keyword List". "Primary keyword" picks the highest-volume variant for each product.
A9: Tip: Tier 1 alone (batches 1–9) covers every product's core keyword plus brand, category and concern terms — start there.
A11: Tiers
A12: Tier 1 — core product keyword (brand + product), brand terms, category and concern terms (e.g. "face wash for dry skin").
A13: Tier 2 — product + "uk", product + concentration (e.g. "... eau de parfum").
A14: Tier 3 — commercial modifiers ("buy ... online", "... price") and Google autocomplete suggestions.
... A28: Batches 10–38 were the original full plan and are greyed out as SKIPPED: the 324 useful keywords from them are in T2/T3; the other 2,527 (buy/price/uk/type variants and autocomplete for low-demand products) were left out because even top-100 "+ uk" variants had a median volume of 0.

Sheet Insights
A1: Semrush insights — UK, Tiers 1–3
A2: Figures are formulas over the "Semrush Data" tab (Semrush Keyword Overview, UK database: Tier 1 batches 1–9, Tier 2 T2-1 to T2-3, Tier 3 T3-1 to T3-2, Oct 2026). Volume = average monthly UK searches; KD = keyword difficulty 0–100; 0 / blank = no Semrush data.
A4: Summary
B5: Keywords checked in Semrush | D5: =COUNTA('Semrush Data'!A2:A5000) -> 1314
B6: Keywords with UK search volume | D6: =COUNTIF('Semrush Data'!C2:C5000,">0") -> 735
B7: Products whose primary keyword has volume | D7: =COUNTIF(Products!W2:W600,">0") -> 265
B8: …of which Vilvah & Deyga (of 159) | D8: =COUNTIFS(Products!B2:B600,"Vilvah & Deyga",Products!W2:W600,">0") -> 18
B9: …of which fragrance (of 387) | D9: =COUNTIFS(Products!B2:B600,"Fragrance Catalogue",Products!W2:W600,">0") -> 247
B10: Total monthly searches for product primary keywords | D10: =SUM(Products!W2:W600) -> 221200
A12: What the data says
B13: 1. Fragrance carries the search demand: designer lines (Dior Sauvage, Tom Ford, Gucci, Marc Jacobs, Calvin Klein) get thousands of searches a month, but big retailers own page 1, so pick the lower-KD ones (KD ≤ 20) first.
B14: 2. Vilvah and Deyga product names get very few searches (10–30 a month each); "vilvah" (480), "vilvah milk drops" (390) and "deyga" (140) are the brand terms people use. Brand pages + the Milk Drops page should target these.
B15: 3. The skincare opportunity is non-branded: "moisturiser for dry skin" (2,900), "hair mask for dry hair" (2,400), "hair oil for dry hair" (1,900), "face wash for dry/oily skin" (1,600 each), "shampoo for dandruff" (1,600). Build concern collection pages for these and use the phrases in Vilvah/Deyga product copy and FAQs.
B16: 4. Product pages: keep the brand + product name as H1 (it is the primary keyword for 265 products); add the matching concern phrase in the first paragraph and meta description.
B17: 5. Tier 2 checked perfume-type / "+ uk" variants for the top 100 fragrances and generic ingredient and product-type terms; the Primary keyword per product now picks the highest-volume variant.
A19: Top 50 hero products
A20: Ranked by primary-keyword volume, KD as tie-break. Suggested set for the "premium description rewrite × 50" in the quote. Ranking is a snapshot; volumes are live formulas.
A21: ID | B21: Product | C21: Primary keyword | D21: Volume | E21: KD | F21: CPC ($) | G21: Ease | H21: Where to use
A22: FR-115 | B22: Dior Sauvage Eau de Parfum 100ml + 10ml Men's Gift Set | C22: =INDEX(Products!$V$2:$V$600,MATCH(A22,Products!$A$2:$A$600,0)) -> dior sauvage | D22: =IFERROR(INDEX('Semrush Data'!$C$2:$C$5000,MATCH(C22,'Semrush Data'!$A$2:$A$5000,0)),"") -> 60500 | E22: =IFERROR(INDEX('Semrush Data'!$D$2:$D$5000,MATCH(C22,'Semrush Data'!$A$2:$A$5000,0)),"") -> 38 | F22: =IFERROR(INDEX('Semrush Data'!$E$2:$E$5000,MATCH(C22,'Semrush Data'!$A$2:$A$5000,0)),"") -> 0.57 | G22: =IF(E22="","",IF(E22<=20,"Easier",IF(E22<=35,"Medium","Hard"))) -> Hard | H22: H1 + meta title + first sentence; long-form description (premium rewrite)
A23: FR-378 | B23: Tom Ford Black Orchid Parfum 100ml Unisex | C23: =INDEX(Products!$V$2:$V$600,MATCH(A23,Products!$A$2:$A$600,0)) -> tom ford black orchid | D23: =IFERROR(INDEX('Semrush Data'!$C$2:$C$5000,MATCH(C23,'Semrush Data'!$A$2:$A$5000,0)),"") -> 22200 | E23: =IFERROR(INDEX('Semrush Data'!$D$2:$D$5000,MATCH(C23,'Semrush Data'!$A$2:$A$5000,0)),"") -> 22 | F23: =IFERROR(INDEX('Semrush Data'!$E$2:$E$5000,MATCH(C23,'Semrush Data'!$A$2:$A$5000,0)),"") -> 0.49 | G23: =IF(E23="","",IF(E23<=20,"Easier",IF(E23<=35,"Medium","Hard"))) -> Medium | H23: H1 + meta title + first sentence; long-form description (premium rewrite)
A24: FR-375 | B24: Tom Ford Oud Wood Eau de Parfum 50ml Unisex | C24: =INDEX(Products!$V$2:$V$600,MATCH(A24,Products!$A$2:$A$600,0)) -> tom ford oud wood | D24: =IFERROR(INDEX('Semrush Data'!$C$2:$C$5000,MATCH(C24,'Semrush Data'!$A$2:$A$5000,0)),"") -> 18100 | E24: =IFERROR(INDEX('Semrush Data'!$D$2:$D$5000,MATCH(C24,'Semrush Data'!$A$2:$A$5000,0)),"") -> 16 | F24: =IFERROR(INDEX('Semrush Data'!$E$2:$E$5000,MATCH(C24,'Semrush Data'!$A$2:$A$5000,0)),"") -> 0.54 | G24: =IF(E24="","",IF(E24<=20,"Easier",IF(E24<=35,"Medium","Hard"))) -> Easier | H24: H1 + meta title + first sentence; long-form description (premium rewrite)
A25: FR-269 | B25: Joop! Homme Eau de Toilette 200ml – Men's Warm Spicy Long lasting Fragrance | C25: =INDEX(Products!$V$2:$V$600,MATCH(A25,Products!$A$2:$A$600,0)) -> joop! homme | D25: =IFERROR(INDEX('Semrush Data'!$C$2:$C$5000,MATCH(C25,'Semrush Data'!$A$2:$A$5000,0)),"") -> 9900 | E25: =IFERROR(INDEX('Semrush Data'!$D$2:$D$5000,MATCH(C25,'Semrush Data'!$A$2:$A$5000,0)),"") -> 23 | F25: =IFERROR(INDEX('Semrush Data'!$E$2:$E$5000,MATCH(C25,'Semrush Data'!$A$2:$A$5000,0)),"") -> 0.36 | G25: =IF(E25="","",IF(E25<=20,"Easier",IF(E25<=35,"Medium","Hard"))) -> Medium | H25: H1 + meta title + first sentence; long-form description (premium rewrite)
A26: FR-379 | B26: Tom Ford Noir Extreme Parfum 100ml for Men | C26: =INDEX(Products!$V$2:$V$600,MATCH(A26,Products!$A$2:$A$600,0)) -> tom ford noir extreme | D26: =IFERROR(INDEX('Semrush Data'!$C$2:$C$5000,MATCH(C26,'Semrush Data'!$A$2:$A$5000,0)),"") -> 8100 | E26: =IFERROR(INDEX('Semrush Data'!$D$2:$D$5000,MATCH(C26,'Semrush Data'!$A$2:$A$5000,0)),"") -> 15 | F26: =IFERROR(INDEX('Semrush Data'!$E$2:$E$5000,MATCH(C26,'Semrush Data'!$A$2:$A$5000,0)),"") -> 0.59 | G26: =IF(E26="","",IF(E26<=20,"Easier",IF(E26<=35,"Medium","Hard"))) -> Easier | H26: H1 + meta title + first sentence; long-form description (premium rewrite)
A27: FR-220 | B27: Gucci Intense Oud Eau de Parfum Spray 90ml – Long Lasting Luxury Unisex Oud Fragrance | C27: =INDEX(Products!$V$2:$V$600,MATCH(A27,Products!$A$2:$A$600,0)) -> gucci intense oud | D27: =IFERROR(INDEX('Semrush Data'!$C$2:$C$5000,MATCH(C27,'Semrush Data'!$A$2:$A$5000,0)),"") -> 6600 | E27: =IFERROR(INDEX('Semrush Data'!$D$2:$D$5000,MATCH(C27,'Semrush Data'!$A$2:$A$5000,0)),"") -> 21 | F27: =IFERROR(INDEX('Semrush Data'!$E$2:$E$5000,MATCH(C27,'Semrush Data'!$A$2:$A$5000,0)),"") -> 0.44 | G27: =IF(E27="","",IF(E27<=20,"Easier",IF(E27<=35,"Medium","Hard"))) -> Medium | H27: H1 + meta title + first sentence; long-form description (premium rewrite)
A28: FR-292 | B28: Marc Jacobs Perfect Eau de Parfum 50ml – Women's Floral Fragrance | C28: =INDEX(Products!$V$2:$V$600,MATCH(A28,Products!$A$2:$A$600,0)) -> marc jacobs perfect | D28: =IFERROR(INDEX('Semrush Data'!$C$2:$C$5000,MATCH(C28,'Semrush Data'!$A$2:$A$5000,0)),"") -> 6600 | E28: =IFERROR(INDEX('Semrush Data'!$D$2:$D$5000,MATCH(C28,'Semrush Data'!$A$2:$A$5000,0)),"") -> 26 | F28: =IFERROR(INDEX('Semrush Data'!$E$2:$E$5000,MATCH(C28,'Semrush Data'!$A$2:$A$5000,0)),"") -> 0.36 | G28: =IF(E28="","",IF(E28<=20,"Easier",IF(E28<=35,"Medium","Hard"))) -> Medium | H28: H1 + meta title + first sentence; long-form description (premium rewrite)
A29: FR-077 | B29: Calvin Klein Eternity Eau de Parfum – Women's Classic Floral Fragrance | C29: =INDEX(Products!$V$2:$V$600,MATCH(A29,Products!$A$2:$A$600,0)) -> calvin klein eternity | D29: =IFERROR(INDEX('Semrush Data'!$C$2:$C$5000,MATCH(C29,'Semrush Data'!$A$2:$A$5000,0)),"") -> 4400 | E29: =IFERROR(INDEX('Semrush Data'!$D$2:$D$5000,MATCH(C29,'Semrush Data'!$A$2:$A$5000,0)),"") -> 21 | F29: =IFERROR(INDEX('Semrush Data'!$E$2:$E$5000,MATCH(C29,'Semrush Data'!$A$2:$A$5000,0)),"") -> 0.37 | G29: =IF(E29="","",IF(E29<=20,"Easier",IF(E29<=35,"Medium","Hard"))) -> Medium | H29: H1 + meta title + first sentence; long-form description (premium rewrite)
A30: FR-257 | B30: Hugo Boss Bottled Eau de Parfum 200ml for Men | C30: =INDEX(Products!$V$2:$V$600,MATCH(A30,Products!$A$2:$A$600,0)) -> hugo boss bottled | D30: =IFERROR(INDEX('Semrush Data'!$C$2:$C$5000,MATCH(C30,'Semrush Data'!$A$2:$A$5000,0)),"") -> 4400 | E30: =IFERROR(INDEX('Semrush Data'!$D$2:$D$5000,MATCH(C30,'Semrush Data'!$A$2:$A$5000,0)),"") -> 28 | F30: =IFERROR(INDEX('Semrush Data'!$E$2:$E$5000,MATCH(C30,'Semrush Data'!$A$2:$A$5000,0)),"") -> 0.45 | G30: =IF(E30="","",IF(E30<=20,"Easier",IF(E30<=35,"Medium","Hard"))) -> Medium | H30: H1 + meta title + first sentence; long-form description (premium rewrite)
A31: FR-217 | B31: Gucci Flora Gorgeous Gardenia Eau de Parfum 50ml – Women's Floral Fragrance | C31: =INDEX(Products!$V$2:$V$600,MATCH(A31,Products!$A$2:$A$600,0)) -> gucci flora gorgeous gardenia | D31: =IFERROR(INDEX('Semrush Data'!$C$2:$C$5000,MATCH(C31,'Semrush Data'!$A$2:$A$5000,0)),"") -> 4400 | E31: =IFERROR(INDEX('Semrush Data'!$D$2:$D$5000,MATCH(C31,'Semrush Data'!$A$2:$A$5000,0)),"") -> 29 | F31: =IFERROR(INDEX('Semrush Data'!$E$2:$E$5000,MATCH(C31,'Semrush Data'!$A$2:$A$5000,0)),"") -> 0.43 | G31: =IF(E31="","",IF(E31<=20,"Easier",IF(E31<=35,"Medium","Hard"))) -> Medium | H31: H1 + meta title + first sentence; long-form description (premium rewrite)
A32: FR-374 | B32: Tom Ford Neroli Portofino Eau de Parfum 50ml Unisex | C32: =INDEX(Products!$V$2:$V$600,MATCH(A32,Products!$A$2:$A$600,0)) -> tom ford neroli portofino | D32: =IFERROR(INDEX('Semrush Data'!$C$2:$C$5000,MATCH(C32,'Semrush Data'!$A$2:$A$5000,0)),"") -> 3600 | E32: =IFERROR(INDEX('Semrush Data'!$D$2:$D$5000,MATCH(C32,'Semrush Data'!$A$2:$A$5000,0)),"") -> 14 | F32: =IFERROR(INDEX('Semrush Data'!$E$2:$E$5000,MATCH(C32,'Semrush Data'!$A$2:$A$5000,0)),"") -> 0.63 | G32: =IF(E32="","",IF(E32<=20,"Easier",IF(E32<=35,"Medium","Hard"))) -> Easier | H32: H1 + meta title + first sentence; long-form description (premium rewrite)
A33: FR-095 | B33: Chloé Nomade Eau de Parfum 50ml – Women's Floral Chypre Fragrance | C33: =INDEX(Products!$V$2:$V$600,MATCH(A33,Products!$A$2:$A$600,0)) -> chloe nomade | D33: =IFERROR(INDEX('Semrush Data'!$C$2:$C$5000,MATCH(C33,'Semrush Data'!$A$2:$A$5000,0)),"") -> 2900 | E33: =IFERROR(INDEX('Semrush Data'!$D$2:$D$5000,MATCH(C33,'Semrush Data'!$A$2:$A$5000,0)),"") -> 22 | F33: =IFERROR(INDEX('Semrush Data'!$E$2:$E$5000,MATCH(C33,'Semrush Data'!$A$2:$A$5000,0)),"") -> 0.47 | G33: =IF(E33="","",IF(E33<=20,"Easier",IF(E33<=35,"Medium","Hard"))) -> Medium | H33: H1 + meta title + first sentence; long-form description (premium rewrite)
... A71: FR-094 | B71: Carolina Herrera Very Good Girl Glam Parfum 50ml – Women's Floral Fruity Gourmand Fragrance | C71: =INDEX(Products!$V$2:$V$600,MATCH(A71,Products!$A$2:$A$600,0)) -> carolina herrera very good girl glam | D71: =IFERROR(INDEX('Semrush Data'!$C$2:$C$5000,MATCH(C71,'Semrush Data'!$A$2:$A$5000,0)),"") -> 320 | E71: =IFERROR(INDEX('Semrush Data'!$D$2:$D$5000,MATCH(C71,'Semrush Data'!$A$2:$A$5000,0)),"") -> 20 | F71: =IFERROR(INDEX('Semrush Data'!$E$2:$E$5000,MATCH(C71,'Semrush Data'!$A$2:$A$5000,0)),"") -> 0 | G71: =IF(E71="","",IF(E71<=20,"Easier",IF(E71<=35,"Medium","Hard"))) -> Easier | H71: H1 + meta title + first sentence; long-form description (premium rewrite)
A73: Non-branded skincare & haircare opportunities
A74: Category and concern searches: the main organic opportunity for Vilvah & Deyga.
B75: Keyword | C75: Type | D75: Volume | E75: KD | F75: CPC ($) | G75: Ease | H75: Where to use
B76: moisturiser for dry skin | C76: Category / concern | D76: =IFERROR(INDEX('Semrush Data'!$C$2:$C$5000,MATCH(B76,'Semrush Data'!$A$2:$A$5000,0)),"") -> 2900 | E76: =IFERROR(INDEX('Semrush Data'!$D$2:$D$5000,MATCH(B76,'Semrush Data'!$A$2:$A$5000,0)),"") -> 29 | F76: =IFERROR(INDEX('Semrush Data'!$E$2:$E$5000,MATCH(B76,'Semrush Data'!$A$2:$A$5000,0)),"") -> 0.91 | G76: =IF(E76="","",IF(E76<=20,"Easier",IF(E76<=35,"Medium","Hard"))) -> Medium | H76: Concern collection page (H1 + intro + FAQ); product copy & meta description
B77: hair mask for dry hair | C77: Category / concern | D77: =IFERROR(INDEX('Semrush Data'!$C$2:$C$5000,MATCH(B77,'Semrush Data'!$A$2:$A$5000,0)),"") -> 2400 | E77: =IFERROR(INDEX('Semrush Data'!$D$2:$D$5000,MATCH(B77,'Semrush Data'!$A$2:$A$5000,0)),"") -> 13 | F77: =IFERROR(INDEX('Semrush Data'!$E$2:$E$5000,MATCH(B77,'Semrush Data'!$A$2:$A$5000,0)),"") -> 0.75 | G77: =IF(E77="","",IF(E77<=20,"Easier",IF(E77<=35,"Medium","Hard"))) -> Easier | H77: Concern collection page (H1 + intro + FAQ); product copy & meta description
B78: hair oil for dry hair | C78: Category / concern | D78: =IFERROR(INDEX('Semrush Data'!$C$2:$C$5000,MATCH(B78,'Semrush Data'!$A$2:$A$5000,0)),"") -> 1900 | E78: =IFERROR(INDEX('Semrush Data'!$D$2:$D$5000,MATCH(B78,'Semrush Data'!$A$2:$A$5000,0)),"") -> 30 | F78: =IFERROR(INDEX('Semrush Data'!$E$2:$E$5000,MATCH(B78,'Semrush Data'!$A$2:$A$5000,0)),"") -> 0.82 | G78: =IF(E78="","",IF(E78<=20,"Easier",IF(E78<=35,"Medium","Hard"))) -> Medium | H78: Concern collection page (H1 + intro + FAQ); product copy & meta description
B79: face wash for dry skin | C79: Category / concern | D79: =IFERROR(INDEX('Semrush Data'!$C$2:$C$5000,MATCH(B79,'Semrush Data'!$A$2:$A$5000,0)),"") -> 1600 | E79: =IFERROR(INDEX('Semrush Data'!$D$2:$D$5000,MATCH(B79,'Semrush Data'!$A$2:$A$5000,0)),"") -> 29 | F79: =IFERROR(INDEX('Semrush Data'!$E$2:$E$5000,MATCH(B79,'Semrush Data'!$A$2:$A$5000,0)),"") -> 0.85 | G79: =IF(E79="","",IF(E79<=20,"Easier",IF(E79<=35,"Medium","Hard"))) -> Medium | H79: Concern collection page (H1 + intro + FAQ); product copy & meta description
B80: face wash for oily skin | C80: Category / concern | D80: =IFERROR(INDEX('Semrush Data'!$C$2:$C$5000,MATCH(B80,'Semrush Data'!$A$2:$A$5000,0)),"") -> 1600 | E80: =IFERROR(INDEX('Semrush Data'!$D$2:$D$5000,MATCH(B80,'Semrush Data'!$A$2:$A$5000,0)),"") -> 33 | F80: =IFERROR(INDEX('Semrush Data'!$E$2:$E$5000,MATCH(B80,'Semrush Data'!$A$2:$A$5000,0)),"") -> 1.19 | G80: =IF(E80="","",IF(E80<=20,"Easier",IF(E80<=35,"Medium","Hard"))) -> Medium | H80: Concern collection page (H1 + intro + FAQ); product copy & meta description
B81: shampoo for dandruff | C81: Category / concern | D81: =IFERROR(INDEX('Semrush Data'!$C$2:$C$5000,MATCH(B81,'Semrush Data'!$A$2:$A$5000,0)),"") -> 1600 | E81: =IFERROR(INDEX('Semrush Data'!$D$2:$D$5000,MATCH(B81,'Semrush Data'!$A$2:$A$5000,0)),"") -> 31 | F81: =IFERROR(INDEX('Semrush Data'!$E$2:$E$5000,MATCH(B81,'Semrush Data'!$A$2:$A$5000,0)),"") -> 1.05 | G81: =IF(E81="","",IF(E81<=20,"Easier",IF(E81<=35,"Medium","Hard"))) -> Medium | H81: Concern collection page (H1 + intro + FAQ); product copy & meta description
...

Sheet VD Content
A1: ID | B1: Brand | C1: Product | D1: Type | E1: Concern | F1: Target keyword | G1: Target vol. | H1: Target KD | I1: Brand keyword | J1: Brand vol. | K1: Collection page (link to) | L1: H1 | M1: Meta title | N1: Title len | O1: Meta description | P1: Desc len | Q1: Intro paragraph (first lines of product copy) | R1: FAQ ideas (Google autocomplete) | S1: Source description | T1: Claims check
A2: VD-001 | B2: Vilvah | C2: Rosewater Facial Toner | D2: Toners | E2: Skin Nourishment | F2: toner for dry skin | G2: =IFERROR(INDEX('Semrush Data'!$C$2:$C$5000,MATCH(F2,'Semrush Data'!$A$2:$A$5000,0)),"") -> 720 | H2: =IFERROR(INDEX('Semrush Data'!$D$2:$D$5000,MATCH(F2,'Semrush Data'!$A$2:$A$5000,0)),"") -> 16 | I2: vilvah | J2: =IFERROR(INDEX('Semrush Data'!$C$2:$C$5000,MATCH(I2,'Semrush Data'!$A$2:$A$5000,0)),"") -> 480 | K2: /collections/toner-for-dry-skin | L2: Vilvah Rosewater Facial Toner | M2: Vilvah Rosewater Facial Toner | Toner for Dry Skin | N2: =LEN(M2) -> 50 | O2: Buy Vilvah Rosewater Facial Toner, a natural toner for dry skin from Vilvah. Official UK partner: 100% authentic, shipped from the UK, free delivery over £50. | P2: =LEN(O2) -> 158 | Q2: Vilvah Rosewater Facial Toner is a natural toner for dry skin from Vilvah. 100% Natural Rose Hydrosol – Gently extracted from rose petals to preserve skin-loving nutrients. Hydrates & Balances pH – Restores skin's natural moisture and maintains optimal pH levels. Swansura is an official UK partner of Vilvah, so every order is 100% authentic and ships from the UK. | S2: Matched
A3: VD-002 | B3: Vilvah | C3: Hair growth oil | D3: Hair Oil | E3: Hair Thinning & Loss | F3: hair growth oil | G3: =IFERROR(INDEX('Semrush Data'!$C$2:$C$5000,MATCH(F3,'Semrush Data'!$A$2:$A$5000,0)),"") -> 5400 | H3: =IFERROR(INDEX('Semrush Data'!$D$2:$D$5000,MATCH(F3,'Semrush Data'!$A$2:$A$5000,0)),"") -> 21 | I3: vilvah | J3: =IFERROR(INDEX('Semrush Data'!$C$2:$C$5000,MATCH(I3,'Semrush Data'!$A$2:$A$5000,0)),"") -> 480 | K3: /collections/hair-growth-oil | L3: Vilvah Hair Growth Oil | M3: Vilvah Hair Growth Oil – Hair Growth Oil | Swansura | N3: =LEN(M3) -> 51 | O3: Buy Vilvah Hair Growth Oil, a natural hair growth oil from Vilvah. Official UK partner: 100% authentic, shipped from the UK, free delivery over £50. | P3: =LEN(O3) -> 148 | Q3: Vilvah Hair Growth Oil is a natural hair growth oil from Vilvah. Combines Pumpkin Seed, Kalonji, Castor, and Grapeseed Oils to nourish and revitalize hair. Enriched with Vitamin E and essential fatty acids to fortify hair from root to tip. Swansura is an official UK partner of Vilvah, so every order is 100% authentic and ships from the UK. | R3: vilvah hair growth oil review · vilvah hair growth oil how to use · vilvah hair growth oil benefits · vilvah hair growth oil india · vilvah hair growth oil review before and after · vilvah hair growth oil amazon | S3: Matched | T3: Review: source copy has medical-style claims (kept out of intro)
A4: VD-003 | B4: Vilvah | C4: Classic Goatmilk Soap | D4: Bath & Body Wash | E4: Body Cleansing | F4: natural body wash | G4: =IFERROR(INDEX('Semrush Data'!$C$2:$C$5000,MATCH(F4,'Semrush Data'!$A$2:$A$5000,0)),"") -> 1300 | H4: =IFERROR(INDEX('Semrush Data'!$D$2:$D$5000,MATCH(F4,'Semrush Data'!$A$2:$A$5000,0)),"") -> 19 | I4: vilvah | J4: =IFERROR(INDEX('Semrush Data'!$C$2:$C$5000,MATCH(I4,'Semrush Data'!$A$2:$A$5000,0)),"") -> 480 | K4: /collections/shower-gel-body-wash | L4: Vilvah Classic Goatmilk Soap | M4: Vilvah Classic Goatmilk Soap – Natural Body Wash | Swansura | N4: =LEN(M4) -> 59 | O4: Buy Vilvah Classic Goatmilk Soap, a natural body wash from Vilvah. Official UK partner: 100% authentic, shipped from the UK, free delivery over £50. | P4: =LEN(O4) -> 148 | Q4: Vilvah Classic Goatmilk Soap is a natural body wash from Vilvah. Swansura is an official UK partner of Vilvah, so every order is 100% authentic and ships from the UK. | S4: Not found – write from pack
A5: VD-004 | B5: Vilvah | C5: Deo Shot - Rose and Vanilla | D5: Deodorant | E5: Body Hydration | F5: natural deodorant | G5: =IFERROR(INDEX('Semrush Data'!$C$2:$C$5000,MATCH(F5,'Semrush Data'!$A$2:$A$5000,0)),"") -> 6600 | H5: =IFERROR(INDEX('Semrush Data'!$D$2:$D$5000,MATCH(F5,'Semrush Data'!$A$2:$A$5000,0)),"") -> 26 | I5: vilvah | J5: =IFERROR(INDEX('Semrush Data'!$C$2:$C$5000,MATCH(I5,'Semrush Data'!$A$2:$A$5000,0)),"") -> 480 | K5: /collections/deodorant | L5: Vilvah Deo Shot - Rose and Vanilla | M5: Vilvah Deo Shot - Rose and Vanilla | Natural Deodorant | N5: =LEN(M5) -> 54 | O5: Buy Vilvah Deo Shot - Rose and Vanilla, a natural deodorant from Vilvah. Official UK partner: 100% authentic, shipped from the UK, free delivery over £50. | P5: =LEN(O5) -> 154 | Q5: Vilvah Deo Shot - Rose and Vanilla is a natural deodorant from Vilvah. 24-Hour Odour Protection: Provides all-day freshness by neutralizing odour-causing bacteria. Crafted with virgin coconut oil, shea butter, and jojoba oil to nourish and protect the skin. Swansura is an official UK partner of Vilvah, so every order is 100% authentic and ships from the UK. | S5: Matched
A6: VD-005 | B6: Vilvah | C6: Skin finish Sunscreen SPF 50 | D6: SPF for Face | E6: Sun Protection | F6: natural sunscreen | G6: =IFERROR(INDEX('Semrush Data'!$C$2:$C$5000,MATCH(F6,'Semrush Data'!$A$2:$A$5000,0)),"") -> 3600 | H6: =IFERROR(INDEX('Semrush Data'!$D$2:$D$5000,MATCH(F6,'Semrush Data'!$A$2:$A$5000,0)),"") -> 24 | I6: vilvah | J6: =IFERROR(INDEX('Semrush Data'!$C$2:$C$5000,MATCH(I6,'Semrush Data'!$A$2:$A$5000,0)),"") -> 480 | K6: /collections/natural-sunscreen | L6: Vilvah Skin Finish Sunscreen SPF 50 | M6: Vilvah Skin Finish Sunscreen SPF 50 | Natural Sunscreen | N6: =LEN(M6) -> 55 | O6: Buy Vilvah Skin Finish Sunscreen SPF 50, a natural sunscreen from Vilvah. Official UK partner: 100% authentic, shipped from the UK, free delivery over £50. | P6: =LEN(O6) -> 155 | Q6: Vilvah Skin Finish Sunscreen SPF 50 is a natural sunscreen from Vilvah. Swansura is an official UK partner of Vilvah, so every order is 100% authentic and ships from the UK. | S6: Matched – no usable facts, add 1–2 from pack
A7: VD-006 | B7: Vilvah | C7: Milk Powder Face Wash | D7: Cleansers | E7: Skin Nourishment | F7: face wash for oily skin | G7: =IFERROR(INDEX('Semrush Data'!$C$2:$C$5000,MATCH(F7,'Semrush Data'!$A$2:$A$5000,0)),"") -> 1600 | H7: =IFERROR(INDEX('Semrush Data'!$D$2:$D$5000,MATCH(F7,'Semrush Data'!$A$2:$A$5000,0)),"") -> 33 | I7: vilvah | J7: =IFERROR(INDEX('Semrush Data'!$C$2:$C$5000,MATCH(I7,'Semrush Data'!$A$2:$A$5000,0)),"") -> 480 | K7: /collections/face-wash-for-oily-skin | L7: Vilvah Milk Powder Face Wash | M7: Vilvah Milk Powder Face Wash | Face Wash for Oily Skin | N7: =LEN(M7) -> 54 | O7: Vilvah Milk Powder Face Wash: a natural face wash for oily skin from Vilvah. Official UK partner: 100% authentic, shipped from the UK, free delivery over £50. | P7: =LEN(O7) -> 158 | Q7: Vilvah Milk Powder Face Wash is a natural face wash for oily skin from Vilvah. Hydrating & pH-balanced – infused with hyaluronic acid to retain moisture, with a skin-friendly pH of 6-7 so skin stays soft, not stripped. Powered by papain enzyme and rice husk powder to buff away dead skin gently. Swansura is an official UK partner of Vilvah, so every order is 100% authentic and ships from the UK. | R7: vilvah milk powder face wash review · vilvah milk powder face wash benefits · vilvah milk powder face wash price · vilvah milk powder face wash how to use · vilvah milk powder face wash and serum · vilvah milk powder face wash amazon | S7: Matched
A8: VD-007 | B8: Vilvah | C8: Ultra Moisturising Cream | D8: Moisturisers | E8: Dry Skin | F8: moisturiser for dry skin | G8: =IFERROR(INDEX('Semrush Data'!$C$2:$C$5000,MATCH(F8,'Semrush Data'!$A$2:$A$5000,0)),"") -> 2900 | H8: =IFERROR(INDEX('Semrush Data'!$D$2:$D$5000,MATCH(F8,'Semrush Data'!$A$2:$A$5000,0)),"") -> 29 | I8: vilvah | J8: =IFERROR(INDEX('Semrush Data'!$C$2:$C$5000,MATCH(I8,'Semrush Data'!$A$2:$A$5000,0)),"") -> 480 | K8: /collections/moisturiser-for-dry-skin | L8: Vilvah Ultra Moisturising Cream | M8: Vilvah Ultra Moisturising Cream | Moisturiser for Dry Skin | N8: =LEN(M8) -> 58 | O8: Buy Vilvah Ultra Moisturising Cream, a natural moisturiser for dry skin from Vilvah. Official UK partner, 100% authentic, free UK delivery over £50. | P8: =LEN(O8) -> 148 | Q8: Vilvah Ultra Moisturising Cream is a natural moisturiser for dry skin from Vilvah. Antioxidant-rich ingredients smooth rough patches, leaving the skin soft and supple. The non-greasy formula hydrates without clogging pores, suitable for all skin types. Swansura is an official UK partner of Vilvah, so every order is 100% authentic and ships from the UK. | S8: Matched | T8: Review: source copy has medical-style claims (kept out of intro)
A9: VD-008 | B9: Vilvah | C9: Classic Rose Goatmilk Soap | D9: Bath & Body Wash | E9: Body Cleansing | F9: natural body wash | G9: =IFERROR(INDEX('Semrush Data'!$C$2:$C$5000,MATCH(F9,'Semrush Data'!$A$2:$A$5000,0)),"") -> 1300 | H9: =IFERROR(INDEX('Semrush Data'!$D$2:$D$5000,MATCH(F9,'Semrush Data'!$A$2:$A$5000,0)),"") -> 19 | I9: vilvah | J9: =IFERROR(INDEX('Semrush Data'!$C$2:$C$5000,MATCH(I9,'Semrush Data'!$A$2:$A$5000,0)),"") -> 480 | K9: /collections/shower-gel-body-wash | L9: Vilvah Classic Rose Goatmilk Soap | M9: Vilvah Classic Rose Goatmilk Soap | Natural Body Wash | N9: =LEN(M9) -> 53 | O9: Buy Vilvah Classic Rose Goatmilk Soap, a natural body wash from Vilvah. Official UK partner: 100% authentic, shipped from the UK, free delivery over £50. | P9: =LEN(O9) -> 153 | Q9: Vilvah Classic Rose Goatmilk Soap is a natural body wash from Vilvah. Swansura is an official UK partner of Vilvah, so every order is 100% authentic and ships from the UK. | S9: Not found – write from pack
A10: VD-009 | B10: Vilvah | C10: Goat Milk Body Wash | D10: Bath & Body Wash | E10: Body Cleansing | F10: natural body wash | G10: =IFERROR(INDEX('Semrush Data'!$C$2:$C$5000,MATCH(F10,'Semrush Data'!$A$2:$A$5000,0)),"") -> 1300 | H10: =IFERROR(INDEX('Semrush Data'!$D$2:$D$5000,MATCH(F10,'Semrush Data'!$A$2:$A$5000,0)),"") -> 19 | I10: vilvah | J10: =IFERROR(INDEX('Semrush Data'!$C$2:$C$5000,MATCH(I10,'Semrush Data'!$A$2:$A$5000,0)),"") -> 480 | K10: /collections/shower-gel-body-wash | L10: Vilvah Goat Milk Body Wash | M10: Vilvah Goat Milk Body Wash – Natural Body Wash | Swansura | N10: =LEN(M10) -> 57 | O10: Buy Vilvah Goat Milk Body Wash, a natural body wash from Vilvah. Official UK partner: 100% authentic, shipped from the UK, free delivery over £50. | P10: =LEN(O10) -> 146 | Q10: Vilvah Goat Milk Body Wash is a natural body wash from Vilvah. Enriched with goat milk and virgin coconut oil, this body wash replenishes moisture, making it ideal for dry and sensitive skin types. Designed with a low-foam lather and a pH-balanced 5.5, ensuring a mild cleanse that maintains the skin's natural barrier. Swansura is an official UK partner of Vilvah, so every order is 100% authentic and ships from the UK. | R10: vilvah goat milk body wash review · vilvah goat milk body wash ingredients · vilvah goat milk body wash benefits · vilvah goat milk body soap · vilvah goat milk soap review | S10: Matched
A11: VD-010 | B11: Vilvah | C11: Rose Milk Lip Balm | D11: Lip Care | E11: Dry Lips | F11: lip balm for dry lips | G11: =IFERROR(INDEX('Semrush Data'!$C$2:$C$5000,MATCH(F11,'Semrush Data'!$A$2:$A$5000,0)),"") -> 1000 | H11: =IFERROR(INDEX('Semrush Data'!$D$2:$D$5000,MATCH(F11,'Semrush Data'!$A$2:$A$5000,0)),"") -> 41 | I11: vilvah | J11: =IFERROR(INDEX('Semrush Data'!$C$2:$C$5000,MATCH(I11,'Semrush Data'!$A$2:$A$5000,0)),"") -> 480 | K11: /collections/lip-balm-for-dry-lips | L11: Vilvah Rose Milk Lip Balm | M11: Vilvah Rose Milk Lip Balm – Lip Balm for Dry Lips | Swansura | N11: =LEN(M11) -> 60 | O11: Buy Vilvah Rose Milk Lip Balm, a natural lip balm for dry lips from Vilvah. Official UK partner: 100% authentic, shipped from the UK, free delivery over £50. | P11: =LEN(O11) -> 157 | Q11: Vilvah Rose Milk Lip Balm is a natural lip balm for dry lips from Vilvah. Swansura is an official UK partner of Vilvah, so every order is 100% authentic and ships from the UK. | R11: vilvah rose milk lip balm review · vilvah rose milk lip balm ingredients · vilvah rose milk lip balm price · vilvah lip balm review · vilvah lip balm price | S11: Not found – write from pack
A12: VD-011 | B12: Vilvah | C12: Charcoal Goatmilk Soap | D12: Bath & Body Wash | E12: Body Cleansing | F12: natural body wash | G12: =IFERROR(INDEX('Semrush Data'!$C$2:$C$5000,MATCH(F12,'Semrush Data'!$A$2:$A$5000,0)),"") -> 1300 | H12: =IFERROR(INDEX('Semrush Data'!$D$2:$D$5000,MATCH(F12,'Semrush Data'!$A$2:$A$5000,0)),"") -> 19 | I12: vilvah | J12: =IFERROR(INDEX('Semrush Data'!$C$2:$C$5000,MATCH(I12,'Semrush Data'!$A$2:$A$5000,0)),"") -> 480 | K12: /collections/shower-gel-body-wash | L12: Vilvah Charcoal Goatmilk Soap | M12: Vilvah Charcoal Goatmilk Soap – Natural Body Wash | Swansura | N12: =LEN(M12) -> 60 | O12: Buy Vilvah Charcoal Goatmilk Soap, a natural body wash from Vilvah. Official UK partner: 100% authentic, shipped from the UK, free delivery over £50. | P12: =LEN(O12) -> 149 | Q12: Vilvah Charcoal Goatmilk Soap is a natural body wash from Vilvah. Swansura is an official UK partner of Vilvah, so every order is 100% authentic and ships from the UK. | S12: Not found – write from pack
A13: VD-012 | B13: Vilvah | C13: Cream Conditioner | D13: Conditioner | E13: Hair Nourishment | F13: hair mask for dry hair | G13: =IFERROR(INDEX('Semrush Data'!$C$2:$C$5000,MATCH(F13,'Semrush Data'!$A$2:$A$5000,0)),"") -> 2400 | H13: =IFERROR(INDEX('Semrush Data'!$D$2:$D$5000,MATCH(F13,'Semrush Data'!$A$2:$A$5000,0)),"") -> 13 | I13: vilvah | J13: =IFERROR(INDEX('Semrush Data'!$C$2:$C$5000,MATCH(I13,'Semrush Data'!$A$2:$A$5000,0)),"") -> 480 | K13: /collections/hair-mask-for-dry-hair | L13: Vilvah Cream Conditioner | M13: Vilvah Cream Conditioner – Hair Mask for Dry Hair | Swansura | N13: =LEN(M13) -> 60 | O13: Buy Vilvah Cream Conditioner, a natural hair mask for dry hair from Vilvah. Official UK partner: 100% authentic, shipped from the UK, free delivery over £50. | P13: =LEN(O13) -> 157 | Q13: Vilvah Cream Conditioner is a natural hair mask for dry hair from Vilvah. Swansura is an official UK partner of Vilvah, so every order is 100% authentic and ships from the UK. | R13: vilvah cream conditioner review · vilvah cream conditioner ingredients · how to use vilvah cream conditioner · vilvah conditioner review | S13: Matched – no usable facts, add 1–2 from pack | T13: Review: source copy has medical-style claims (kept out of intro)
A14: VD-013 | B14: Vilvah | C14: Goat Milk Shampoo | D14: Shampoo | E14: Dry Skin | F14: natural shampoo | G14: =IFERROR(INDEX('Semrush Data'!$C$2:$C$5000,MATCH(F14,'Semrush Data'!$A$2:$A$5000,0)),"") -> 3600 | H14: =IFERROR(INDEX('Semrush Data'!$D$2:$D$5000,MATCH(F14,'Semrush Data'!$A$2:$A$5000,0)),"") -> 21 | I14: vilvah | J14: =IFERROR(INDEX('Semrush Data'!$C$2:$C$5000,MATCH(I14,'Semrush Data'!$A$2:$A$5000,0)),"") -> 480 | K14: /collections/natural-shampoo | L14: Vilvah Goat Milk Shampoo | M14: Vilvah Goat Milk Shampoo – Natural Shampoo | Swansura | N14: =LEN(M14) -> 53 | O14: Buy Vilvah Goat Milk Shampoo, a natural shampoo from Vilvah. Official UK partner: 100% authentic, shipped from the UK, free delivery over £50. | P14: =LEN(O14) -> 142 | Q14: Vilvah Goat Milk Shampoo is a natural shampoo from Vilvah. Perfect for dry, damaged, or chemically treated hair, this shampoo leaves the hair feeling clean, manageable, and naturally silky without feeling heavy. Swansura is an official UK partner of Vilvah, so every order is 100% authentic and ships from the UK. | R14: vilvah goat milk shampoo review · vilvah goat milk shampoo price · vilvah goat milk shampoo benefits · vilvah goat milk shampoo ingredients | S14: Matched | T14: Review: source copy has medical-style claims (kept out of intro)
A15: VD-014 | B15: Vilvah | C15: Honey Fix Face Wash | D15: Cleansers | E15: Skin Nourishment | F15: face wash for oily skin | G15: =IFERROR(INDEX('Semrush Data'!$C$2:$C$5000,MATCH(F15,'Semrush Data'!$A$2:$A$5000,0)),"") -> 1600 | H15: =IFERROR(INDEX('Semrush Data'!$D$2:$D$5000,MATCH(F15,'Semrush Data'!$A$2:$A$5000,0)),"") -> 33 | I15: vilvah | J15: =IFERROR(INDEX('Semrush Data'!$C$2:$C$5000,MATCH(I15,'Semrush Data'!$A$2:$A$5000,0)),"") -> 480 | K15: /collections/face-wash-for-oily-skin | L15: Vilvah Honey Fix Face Wash | M15: Vilvah Honey Fix Face Wash | Face Wash for Oily Skin | N15: =LEN(M15) -> 52 | O15: Buy Vilvah Honey Fix Face Wash, a natural face wash for oily skin from Vilvah. Official UK partner: 100% authentic, shipped from the UK, free delivery over £50. | P15: =LEN(O15) -> 160 | Q15: Vilvah Honey Fix Face Wash is a natural face wash for oily skin from Vilvah. Contains 10% raw honey plus fruit extracts (papaya, blackberry, orange peel) to gently exfoliate, brighten, and promote skin radiance. Features witch hazel and Gotu kola extracts to calm inflammation, soothe irritation, and minimize pores. Swansura is an official UK partner of Vilvah, so every order is 100% authentic and ships from the UK. | R15: vilvah honey fix face wash review | S15: Matched
A16: VD-015 | B16: Vilvah | C16: Lip Balm - Lemon | D16: Lip Care | E16: Dry Lips | F16: lip balm for dry lips | G16: =IFERROR(INDEX('Semrush Data'!$C$2:$C$5000,MATCH(F16,'Semrush Data'!$A$2:$A$5000,0)),"") -> 1000 | H16: =IFERROR(INDEX('Semrush Data'!$D$2:$D$5000,MATCH(F16,'Semrush Data'!$A$2:$A$5000,0)),"") -> 41 | I16: vilvah | J16: =IFERROR(INDEX('Semrush Data'!$C$2:$C$5000,MATCH(I16,'Semrush Data'!$A$2:$A$5000,0)),"") -> 480 | K16: /collections/lip-balm-for-dry-lips | L16: Vilvah Lip Balm - Lemon | M16: Vilvah Lip Balm - Lemon – Lip Balm for Dry Lips | Swansura | N16: =LEN(M16) -> 58 | O16: Buy Vilvah Lip Balm - Lemon, a natural lip balm for dry lips from Vilvah. Official UK partner: 100% authentic, shipped from the UK, free delivery over £50. | P16: =LEN(O16) -> 155 | Q16: Vilvah Lip Balm - Lemon is a natural lip balm for dry lips from Vilvah. Lightweight barrier that seals in hydration while letting lips breathe, helping softness last throughout the day. Vegan and free from parabens, sulfates, and synthetic fragrances, ideal for sensitive lips and daily use. Swansura is an official UK partner of Vilvah, so every order is 100% authentic and ships from the UK. | R16: vilvah lip balm lemon · vilvah lemon lip balm review · vilvah lip balm review · vilvah lip balm price | S16: Matched | T16: Review: source copy has medical-style claims (kept out of intro)
A17: VD-016 | B17: Vilvah | C17: Milk Body Lotion | D17: Body Cream & Lotions | E17: Dry Skin | F17: body lotion for dry skin | G17: =IFERROR(INDEX('Semrush Data'!$C$2:$C$5000,MATCH(F17,'Semrush Data'!$A$2:$A$5000,0)),"") -> 1300 | H17: =IFERROR(INDEX('Semrush Data'!$D$2:$D$5000,MATCH(F17,'Semrush Data'!$A$2:$A$5000,0)),"") -> 11 | I17: vilvah | J17: =IFERROR(INDEX('Semrush Data'!$C$2:$C$5000,MATCH(I17,'Semrush Data'!$A$2:$A$5000,0)),"") -> 480 | K17: /collections/body-lotion-for-dry-skin | L17: Vilvah Milk Body Lotion | M17: Vilvah Milk Body Lotion | Body Lotion for Dry Skin | N17: =LEN(M17) -> 50 | O17: Buy Vilvah Milk Body Lotion, a natural body lotion for dry skin from Vilvah. Official UK partner: 100% authentic, shipped from the UK, free delivery over £50. | P17: =LEN(O17) -> 158 | Q17: Vilvah Milk Body Lotion is a natural body lotion for dry skin from Vilvah. Infused with oat milk, ceramides, and olive squalane to hydrate and repair the skin barrier. Formulated without animal-derived ingredients and not tested on animals. Swansura is an official UK partner of Vilvah, so every order is 100% authentic and ships from the UK. | R17: vilvah milk body lotion review · vilvah milk body lotion price | S17: Matched
A18: VD-017 | B18: Vilvah | C18: Milk Face Toner | D18: Toners | E18: Dry Skin | F18: toner for dry skin | G18: =IFERROR(INDEX('Semrush Data'!$C$2:$C$5000,MATCH(F18,'Semrush Data'!$A$2:$A$5000,0)),"") -> 720 | H18: =IFERROR(INDEX('Semrush Data'!$D$2:$D$5000,MATCH(F18,'Semrush Data'!$A$2:$A$5000,0)),"") -> 16 | I18: vilvah | J18: =IFERROR(INDEX('Semrush Data'!$C$2:$C$5000,MATCH(I18,'Semrush Data'!$A$2:$A$5000,0)),"") -> 480 | K18: /collections/toner-for-dry-skin | L18: Vilvah Milk Face Toner | M18: Vilvah Milk Face Toner – Toner for Dry Skin | Swansura | N18: =LEN(M18) -> 54 | O18: Buy Vilvah Milk Face Toner, a natural toner for dry skin from Vilvah. Official UK partner: 100% authentic, shipped from the UK, free delivery over £50. | P18: =LEN(O18) -> 151 | Q18: Vilvah Milk Face Toner is a natural toner for dry skin from Vilvah. Formulated with Earth Marine Water to reduce pore size and provide a smoother skin texture. Effectively removes excess oil and impurities, leaving the skin feeling refreshed and clean. Swansura is an official UK partner of Vilvah, so every order is 100% authentic and ships from the UK. | R18: vilvah milk face toner review · vilvah toner review | S18: Matched | T18: Review: source copy has medical-style claims (kept out of intro)
A19: VD-018 | B19: Vilvah | C19: Milk Mud Mask | D19: Face Masks | E19: Skin Nourishment | F19: face mask | G19: =IFERROR(INDEX('Semrush Data'!$C$2:$C$5000,MATCH(F19,'Semrush Data'!$A$2:$A$5000,0)),"") -> 22200 | H19: =IFERROR(INDEX('Semrush Data'!$D$2:$D$5000,MATCH(F19,'Semrush Data'!$A$2:$A$5000,0)),"") -> 30 | I19: vilvah | J19: =IFERROR(INDEX('Semrush Data'!$C$2:$C$5000,MATCH(I19,'Semrush Data'!$A$2:$A$5000,0)),"") -> 480 | K19: /collections/face-mask | L19: Vilvah Milk Mud Mask | M19: Vilvah Milk Mud Mask | Face Mask | N19: =LEN(M19) -> 32 | O19: Buy Vilvah Milk Mud Mask, a natural face mask from Vilvah. Instantly brightens and rejuvenates dull, tanned skin. Free UK delivery over £50. | P19: =LEN(O19) -> 140 | Q19: Vilvah Milk Mud Mask is a natural face mask from Vilvah. Instantly brightens and rejuvenates dull, tanned skin. Controls excess oil and unclogs pores for a smoother complexion. Swansura is an official UK partner of Vilvah, so every order is 100% authentic and ships from the UK. | R19: vilvah milk mud mask review · vilvah milk mud mask benefits · vilvah milk mud mask ingredients · vilvah milk mud mask how to use · vilvah milk mud mask amazon · vilvah milk mud mask price | S19: Matched
A20: VD-019 | B20: Vilvah | C20: Wild Rose Facemask | D20: Face Masks | E20: Skin Nourishment | F20: face mask | G20: =IFERROR(INDEX('Semrush Data'!$C$2:$C$5000,MATCH(F20,'Semrush Data'!$A$2:$A$5000,0)),"") -> 22200 | H20: =IFERROR(INDEX('Semrush Data'!$D$2:$D$5000,MATCH(F20,'Semrush Data'!$A$2:$A$5000,0)),"") -> 30 | I20: vilvah | J20: =IFERROR(INDEX('Semrush Data'!$C$2:$C$5000,MATCH(I20,'Semrush Data'!$A$2:$A$5000,0)),"") -> 480 | K20: /collections/face-mask | L20: Vilvah Wild Rose Facemask | M20: Vilvah Wild Rose Facemask | Face Mask | N20: =LEN(M20) -> 37 | O20: Buy Vilvah Wild Rose Facemask, a natural face mask from Vilvah. Official UK partner: 100% authentic, shipped from the UK, free delivery over £50. | P20: =LEN(O20) -> 145 | Q20: Vilvah Wild Rose Facemask is a natural face mask from Vilvah. Swansura is an official UK partner of Vilvah, so every order is 100% authentic and ships from the UK. | S20: Not found – write from pack
A21: VD-020 | B21: Vilvah | C21: Aloe Vera Gel | D21: Moisturisers | E21: Skin Nourishment | F21: aloe vera gel | G21: =IFERROR(INDEX('Semrush Data'!$C$2:$C$5000,MATCH(F21,'Semrush Data'!$A$2:$A$5000,0)),"") -> 18100 | H21: =IFERROR(INDEX('Semrush Data'!$D$2:$D$5000,MATCH(F21,'Semrush Data'!$A$2:$A$5000,0)),"") -> 16 | I21: vilvah | J21: =IFERROR(INDEX('Semrush Data'!$C$2:$C$5000,MATCH(I21,'Semrush Data'!$A$2:$A$5000,0)),"") -> 480 | K21: /collections/moisturiser-for-dry-skin | L21: Vilvah Aloe Vera Gel | M21: Vilvah Aloe Vera Gel | Aloe Vera Gel | N21: =LEN(M21) -> 36 | O21: Buy Vilvah Aloe Vera Gel, a natural aloe vera gel from Vilvah. Official UK partner: 100% authentic, shipped from the UK, free delivery over £50. | P21: =LEN(O21) -> 144 | Q21: Vilvah Aloe Vera Gel is a natural aloe vera gel from Vilvah. Pure, cold-stabilised aloe vera juice preserves nutrients for maximum soothing power, ideal for sensitive or sunburned skin. Hydrates deeply without greasy residue; absorbs quickly to leave skin soft, smooth and comfortably moisturised. Swansura is an official UK partner of Vilvah, so every order is 100% authentic and ships from the UK. | R21: vilvah aloe vera gel review · vilvah aloe vera gel ingredients · vilvah aloe vera gel benefits · vilvah aloe vera gel price · vilvah aloe vera gel how to use · vilvah aloe vera gel india | S21: Matched | T21: Review: source copy has medical-style claims (kept out of intro)
A22: VD-021 | B22: Vilvah | C22: Anti-dandruff Hair oil | D22: Hair Oil | E22: Anti-Dandruff | F22: hair growth oil | G22: =IFERROR(INDEX('Semrush Data'!$C$2:$C$5000,MATCH(F22,'Semrush Data'!$A$2:$A$5000,0)),"") -> 5400 | H22: =IFERROR(INDEX('Semrush Data'!$D$2:$D$5000,MATCH(F22,'Semrush Data'!$A$2:$A$5000,0)),"") -> 21 | I22: vilvah | J22: =IFERROR(INDEX('Semrush Data'!$C$2:$C$5000,MATCH(I22,'Semrush Data'!$A$2:$A$5000,0)),"") -> 480 | K22: /collections/hair-growth-oil | L22: Vilvah Anti-dandruff Hair Oil | M22: Vilvah Anti-dandruff Hair Oil – Hair Growth Oil | Swansura | N22: =LEN(M22) -> 58 | O22: Buy Vilvah Anti-dandruff Hair Oil, a natural hair growth oil from Vilvah. Official UK partner: 100% authentic, shipped from the UK, free delivery over £50. | P22: =LEN(O22) -> 155 | Q22: Vilvah Anti-dandruff Hair Oil is a natural hair growth oil from Vilvah. Combines Tea Tree, Neem, Peppermint, and Amla oils to effectively tackle dandruff and nourish the scalp. Calms irritation and balances scalp pH, providing relief from itching and discomfort. Swansura is an official UK partner of Vilvah, so every order is 100% authentic and ships from the UK. | R22: vilvah anti dandruff hair oil review · vilvah anti dandruff oil review | S22: Matched | T22: Review: source copy has medical-style claims (kept out of intro)
A23: VD-022 | B23: Vilvah | C23: Anti-Frizz Hair Serum | D23: Hair Serums | E23: Frizzy Hair | F23: hair serum for frizzy hair | G23: =IFERROR(INDEX('Semrush Data'!$C$2:$C$5000,MATCH(F23,'Semrush Data'!$A$2:$A$5000,0)),"") -> 1000 | H23: =IFERROR(INDEX('Semrush Data'!$D$2:$D$5000,MATCH(F23,'Semrush Data'!$A$2:$A$5000,0)),"") -> 27 | I23: vilvah | J23: =IFERROR(INDEX('Semrush Data'!$C$2:$C$5000,MATCH(I23,'Semrush Data'!$A$2:$A$5000,0)),"") -> 480 | K23: /collections/hair-serum-for-frizzy-hair | L23: Vilvah Anti-Frizz Hair Serum | M23: Vilvah Anti-Frizz Hair Serum | Hair Serum for Frizzy Hair | N23: =LEN(M23) -> 57 | O23: Buy Vilvah Anti-Frizz Hair Serum, a natural hair serum for frizzy hair from Vilvah. Official UK partner, 100% authentic, free UK delivery over £50. | P23: =LEN(O23) -> 147 | Q23: Vilvah Anti-Frizz Hair Serum is a natural hair serum for frizzy hair from Vilvah. Enriched with Black Seed Oil and Hibiscus Oil to nourish and strengthen hair, reducing split ends and breakage. Hibiscus and Arnica Oils impart intense smoothness and a glossy finish, making every day a great hair day. Swansura is an official UK partner of Vilvah, so every order is 100% authentic and ships from the UK. | R23: vilvah anti frizz hair serum review · vilvah anti frizz hair serum price · how to use vilvah anti frizz hair serum | S23: Matched | T23: Review: source copy has medical-style claims (kept out of intro)
A24: VD-023 | B24: Vilvah | C24: Better Ageing Serum | D24: Serums | E24: Anti-Ageing | F24: face serum | G24: =IFERROR(INDEX('Semrush Data'!$C$2:$C$5000,MATCH(F24,'Semrush Data'!$A$2:$A$5000,0)),"") -> 9900 | H24: =IFERROR(INDEX('Semrush Data'!$D$2:$D$5000,MATCH(F24,'Semrush Data'!$A$2:$A$5000,0)),"") -> 30 | I24: vilvah | J24: =IFERROR(INDEX('Semrush Data'!$C$2:$C$5000,MATCH(I24,'Semrush Data'!$A$2:$A$5000,0)),"") -> 480 | K24: /collections/face-serum | L24: Vilvah Better Ageing Serum | M24: Vilvah Better Ageing Serum – Face Serum | Swansura | N24: =LEN(M24) -> 50 | O24: Buy Vilvah Better Ageing Serum, a natural face serum from Vilvah. Official UK partner: 100% authentic, shipped from the UK, free delivery over £50. | P24: =LEN(O24) -> 147 | Q24: Vilvah Better Ageing Serum is a natural face serum from Vilvah. Formulated with plant-derived antioxidants that help neutralise free radicals and slow down visible signs of ageing. Enhances skin elasticity and firmness through natural tightening agents without harsh chemicals. Swansura is an official UK partner of Vilvah, so every order is 100% authentic and ships from the UK. | R24: vilvah better ageing serum review | S24: Matched
A25: VD-024 | B25: Vilvah | C25: Charcoal Facemask | D25: Face Masks | E25: Oily Skin | F25: face mask for oily skin | G25: =IFERROR(INDEX('Semrush Data'!$C$2:$C$5000,MATCH(F25,'Semrush Data'!$A$2:$A$5000,0)),"") -> 210 | H25: =IFERROR(INDEX('Semrush Data'!$D$2:$D$5000,MATCH(F25,'Semrush Data'!$A$2:$A$5000,0)),"") -> 20 | I25: vilvah | J25: =IFERROR(INDEX('Semrush Data'!$C$2:$C$5000,MATCH(I25,'Semrush Data'!$A$2:$A$5000,0)),"") -> 480 | K25: /collections/face-mask-for-oily-skin | L25: Vilvah Charcoal Facemask | M25: Vilvah Charcoal Facemask | Face Mask for Oily Skin | N25: =LEN(M25) -> 50 | O25: Buy Vilvah Charcoal Facemask, a natural face mask for oily skin from Vilvah. Official UK partner: 100% authentic, shipped from the UK, free delivery over £50. | P25: =LEN(O25) -> 158 | Q25: Vilvah Charcoal Facemask is a natural face mask for oily skin from Vilvah. Swansura is an official UK partner of Vilvah, so every order is 100% authentic and ships from the UK. | S25: Not found – write from pack
A26: VD-025 | B26: Vilvah | C26: Cookie n Cream Body Mask | D26: Body Cream & Lotions | E26: Dry Skin | F26: body lotion for dry skin | G26: =IFERROR(INDEX('Semrush Data'!$C$2:$C$5000,MATCH(F26,'Semrush Data'!$A$2:$A$5000,0)),"") -> 1300 | H26: =IFERROR(INDEX('Semrush Data'!$D$2:$D$5000,MATCH(F26,'Semrush Data'!$A$2:$A$5000,0)),"") -> 11 | I26: vilvah | J26: =IFERROR(INDEX('Semrush Data'!$C$2:$C$5000,MATCH(I26,'Semrush Data'!$A$2:$A$5000,0)),"") -> 480 | K26: /collections/body-lotion-for-dry-skin | L26: Vilvah Cookie N Cream Body Mask | M26: Vilvah Cookie N Cream Body Mask | Body Lotion for Dry Skin | N26: =LEN(M26) -> 58 | O26: Buy Vilvah Cookie N Cream Body Mask, a natural body lotion for dry skin from Vilvah. Official UK partner, 100% authentic, free UK delivery over £50. | P26: =LEN(O26) -> 148 | Q26: Vilvah Cookie N Cream Body Mask is a natural body lotion for dry skin from Vilvah. Enriched with almond milk and coffee, known for their moisturizing and antioxidant properties. Regular use promotes a smoother, more even-toned complexion. Swansura is an official UK partner of Vilvah, so every order is 100% authentic and ships from the UK. | S26: Matched | T26: Review: source copy has medical-style claims (kept out of intro)
A27: VD-026 | B27: Vilvah | C27: Cookie n Cream Body Polish | D27: Body Scrub & Exfoliators | E27: Dull Skin | F27: body scrub | G27: =IFERROR(INDEX('Semrush Data'!$C$2:$C$5000,MATCH(F27,'Semrush Data'!$A$2:$A$5000,0)),"") -> 12100 | H27: =IFERROR(INDEX('Semrush Data'!$D$2:$D$5000,MATCH(F27,'Semrush Data'!$A$2:$A$5000,0)),"") -> 18 | I27: vilvah | J27: =IFERROR(INDEX('Semrush Data'!$C$2:$C$5000,MATCH(I27,'Semrush Data'!$A$2:$A$5000,0)),"") -> 480 | K27: /collections/body-scrub | L27: Vilvah Cookie N Cream Body Polish | M27: Vilvah Cookie N Cream Body Polish – Body Scrub | Swansura | N27: =LEN(M27) -> 57 | O27: Buy Vilvah Cookie N Cream Body Polish, a natural body scrub from Vilvah. Official UK partner: 100% authentic, shipped from the UK, free delivery over £50. | P27: =LEN(O27) -> 154 | Q27: Vilvah Cookie N Cream Body Polish is a natural body scrub from Vilvah. Coffee powder effectively sloughs away dead skin cells, unclogs pores, and fades tan, revealing smoother skin. Infused with almond milk, shea butter, and argan oil to nourish and moisturize, leaving skin soft and supple. Swansura is an official UK partner of Vilvah, so every order is 100% authentic and ships from the UK. | S27: Matched | T27: Review: source copy has medical-style claims (kept out of intro)
A28: VD-027 | B28: Vilvah | C28: Cream Face Wash (Fragrance free) | D28: Cleansers | E28: Skin Nourishment | F28: face wash for dry skin | G28: =IFERROR(INDEX('Semrush Data'!$C$2:$C$5000,MATCH(F28,'Semrush Data'!$A$2:$A$5000,0)),"") -> 1600 | H28: =IFERROR(INDEX('Semrush Data'!$D$2:$D$5000,MATCH(F28,'Semrush Data'!$A$2:$A$5000,0)),"") -> 29 | I28: vilvah | J28: =IFERROR(INDEX('Semrush Data'!$C$2:$C$5000,MATCH(I28,'Semrush Data'!$A$2:$A$5000,0)),"") -> 480 | K28: /collections/face-wash-for-dry-skin | L28: Vilvah Cream Face Wash (Fragrance Free) | M28: Vilvah Cream Face Wash (Fragrance Free) | Swansura UK | N28: =LEN(M28) -> 53 | O28: Buy Vilvah Cream Face Wash (Fragrance Free), a natural face wash for dry skin from Vilvah. Official UK partner, 100% authentic, free UK delivery over £50. | P28: =LEN(O28) -> 154 | Q28: Vilvah Cream Face Wash (Fragrance Free) is a natural face wash for dry skin from Vilvah. Swansura is an official UK partner of Vilvah, so every order is 100% authentic and ships from the UK. | S28: Not found – write from pack
A29: VD-028 | B29: Vilvah | C29: Cucumber, Curd & Mint Soap | D29: Bath & Body Wash | E29: Body Cleansing | F29: natural body wash | G29: =IFERROR(INDEX('Semrush Data'!$C$2:$C$5000,MATCH(F29,'Semrush Data'!$A$2:$A$5000,0)),"") -> 1300 | H29: =IFERROR(INDEX('Semrush Data'!$D$2:$D$5000,MATCH(F29,'Semrush Data'!$A$2:$A$5000,0)),"") -> 19 | I29: vilvah | J29: =IFERROR(INDEX('Semrush Data'!$C$2:$C$5000,MATCH(I29,'Semrush Data'!$A$2:$A$5000,0)),"") -> 480 | K29: /collections/shower-gel-body-wash | L29: Vilvah Cucumber, Curd & Mint Soap | M29: Vilvah Cucumber, Curd & Mint Soap | Natural Body Wash | N29: =LEN(M29) -> 53 | O29: Buy Vilvah Cucumber, Curd & Mint Soap, a natural body wash from Vilvah. Official UK partner: 100% authentic, shipped from the UK, free delivery over £50. | P29: =LEN(O29) -> 153 | Q29: Vilvah Cucumber, Curd & Mint Soap is a natural body wash from Vilvah. Swansura is an official UK partner of Vilvah, so every order is 100% authentic and ships from the UK. | S29: Not found – write from pack
A30: VD-029 | B30: Vilvah | C30: Deo shot - Lavender and Sage | D30: Deodorant | E30: Body Hydration | F30: natural deodorant | G30: =IFERROR(INDEX('Semrush Data'!$C$2:$C$5000,MATCH(F30,'Semrush Data'!$A$2:$A$5000,0)),"") -> 6600 | H30: =IFERROR(INDEX('Semrush Data'!$D$2:$D$5000,MATCH(F30,'Semrush Data'!$A$2:$A$5000,0)),"") -> 26 | I30: vilvah | J30: =IFERROR(INDEX('Semrush Data'!$C$2:$C$5000,MATCH(I30,'Semrush Data'!$A$2:$A$5000,0)),"") -> 480 | K30: /collections/deodorant | L30: Vilvah Deo Shot - Lavender and Sage | M30: Vilvah Deo Shot - Lavender and Sage | Natural Deodorant | N30: =LEN(M30) -> 55 | O30: Buy Vilvah Deo Shot - Lavender and Sage, a natural deodorant from Vilvah. Official UK partner: 100% authentic, shipped from the UK, free delivery over £50. | P30: =LEN(O30) -> 155 | Q30: Vilvah Deo Shot - Lavender and Sage is a natural deodorant from Vilvah. Made with natural ingredients, free from alcohol, silicones, and synthetic fragrances, ensuring a gentle experience for sensitive skin. Offers up to 24 hours of odour protection, keeping you feeling fresh throughout the day. Swansura is an official UK partner of Vilvah, so every order is 100% authentic and ships from the UK. | S30: Matched
A31: VD-030 | B31: Vilvah | C31: Foot Cream | D31: Body Cream & Lotions | E31: Dry Skin | F31: foot cream | G31: =IFERROR(INDEX('Semrush Data'!$C$2:$C$5000,MATCH(F31,'Semrush Data'!$A$2:$A$5000,0)),"") -> 5400 | H31: =IFERROR(INDEX('Semrush Data'!$D$2:$D$5000,MATCH(F31,'Semrush Data'!$A$2:$A$5000,0)),"") -> 22 | I31: vilvah | J31: =IFERROR(INDEX('Semrush Data'!$C$2:$C$5000,MATCH(I31,'Semrush Data'!$A$2:$A$5000,0)),"") -> 480 | K31: /collections/body-lotion-for-dry-skin | L31: Vilvah Foot Cream | M31: Vilvah Foot Cream | Foot Cream | N31: =LEN(M31) -> 30 | O31: Buy Vilvah Foot Cream, a natural foot cream from Vilvah. Official UK partner: 100% authentic, shipped from the UK, free delivery over £50. | P31: =LEN(O31) -> 138 | Q31: Vilvah Foot Cream is a natural foot cream from Vilvah. Dermatologically tested and free from harsh chemicals, making it safe for sensitive skin. Ideal for both men and women; apply daily for best results, especially before bedtime. Swansura is an official UK partner of Vilvah, so every order is 100% authentic and ships from the UK. | R31: vilvah foot cream review · vilvah foot cream price · vilvah foot cream ingredients | S31: Matched | T31: Review: source copy has medical-style claims (kept out of intro)
A32: VD-031 | B32: Vilvah | C32: Goat Milk Hair Mask | D32: Hair Masks | E32: Dry Hair | F32: hair mask for dry hair | G32: =IFERROR(INDEX('Semrush Data'!$C$2:$C$5000,MATCH(F32,'Semrush Data'!$A$2:$A$5000,0)),"") -> 2400 | H32: =IFERROR(INDEX('Semrush Data'!$D$2:$D$5000,MATCH(F32,'Semrush Data'!$A$2:$A$5000,0)),"") -> 13 | I32: vilvah | J32: =IFERROR(INDEX('Semrush Data'!$C$2:$C$5000,MATCH(I32,'Semrush Data'!$A$2:$A$5000,0)),"") -> 480 | K32: /collections/hair-mask-for-dry-hair | L32: Vilvah Goat Milk Hair Mask | M32: Vilvah Goat Milk Hair Mask | Hair Mask for Dry Hair | N32: =LEN(M32) -> 51 | O32: Buy Vilvah Goat Milk Hair Mask, a natural hair mask for dry hair from Vilvah. Official UK partner: 100% authentic, shipped from the UK, free delivery over £50. | P32: =LEN(O32) -> 159 | Q32: Vilvah Goat Milk Hair Mask is a natural hair mask for dry hair from Vilvah. Enriched with goat milk and ceramides to restore the hair’s barrier, reduce breakage, and strengthen from root to tip. Lightweight yet intensely nourishing formula tames flyaways and smooths frizz without leaving hair greasy. Swansura is an official UK partner of Vilvah, so every order is 100% authentic and ships from the UK. | R32: vilvah goat milk hair mask review · vilvah goat milk hair mask ingredients · how to use vilvah goat milk hair mask · how to use vilvah hair mask | S32: Matched
A33: VD-032 | B33: Vilvah | C33: Hair growth oil | D33: Hair Oil | E33: Hair Thinning & Loss | F33: hair growth oil | G33: =IFERROR(INDEX('Semrush Data'!$C$2:$C$5000,MATCH(F33,'Semrush Data'!$A$2:$A$5000,0)),"") -> 5400 | H33: =IFERROR(INDEX('Semrush Data'!$D$2:$D$5000,MATCH(F33,'Semrush Data'!$A$2:$A$5000,0)),"") -> 21 | I33: vilvah | J33: =IFERROR(INDEX('Semrush Data'!$C$2:$C$5000,MATCH(I33,'Semrush Data'!$A$2:$A$5000,0)),"") -> 480 | K33: /collections/hair-growth-oil | L33: Vilvah Hair Growth Oil | M33: Vilvah Hair Growth Oil – Hair Growth Oil | Swansura | N33: =LEN(M33) -> 51 | O33: Buy Vilvah Hair Growth Oil, a natural hair growth oil from Vilvah. Official UK partner: 100% authentic, shipped from the UK, free delivery over £50. | P33: =LEN(O33) -> 148 | Q33: Vilvah Hair Growth Oil is a natural hair growth oil from Vilvah. Combines Pumpkin Seed, Kalonji, Castor, and Grapeseed Oils to nourish and revitalize hair. Enriched with Vitamin E and essential fatty acids to fortify hair from root to tip. Swansura is an official UK partner of Vilvah, so every order is 100% authentic and ships from the UK. | R33: vilvah hair growth oil review · vilvah hair growth oil how to use · vilvah hair growth oil benefits · vilvah hair growth oil india · vilvah hair growth oil review before and after · vilvah hair growth oil amazon | S33: Matched | T33: Review: source copy has medical-style claims (kept out of intro)
A34: VD-033 | B34: Vilvah | C34: Hair growth oil | D34: Hair Oil | E34: Hair Thinning & Loss | F34: hair growth oil | G34: =IFERROR(INDEX('Semrush Data'!$C$2:$C$5000,MATCH(F34,'Semrush Data'!$A$2:$A$5000,0)),"") -> 5400 | H34: =IFERROR(INDEX('Semrush Data'!$D$2:$D$5000,MATCH(F34,'Semrush Data'!$A$2:$A$5000,0)),"") -> 21 | I34: vilvah | J34: =IFERROR(INDEX('Semrush Data'!$C$2:$C$5000,MATCH(I34,'Semrush Data'!$A$2:$A$5000,0)),"") -> 480 | K34: /collections/hair-growth-oil | L34: Vilvah Hair Growth Oil | M34: Vilvah Hair Growth Oil – Hair Growth Oil | Swansura | N34: =LEN(M34) -> 51 | O34: Buy Vilvah Hair Growth Oil, a natural hair growth oil from Vilvah. Official UK partner: 100% authentic, shipped from the UK, free delivery over £50. | P34: =LEN(O34) -> 148 | Q34: Vilvah Hair Growth Oil is a natural hair growth oil from Vilvah. Combines Pumpkin Seed, Kalonji, Castor, and Grapeseed Oils to nourish and revitalize hair. Enriched with Vitamin E and essential fatty acids to fortify hair from root to tip. Swansura is an official UK partner of Vilvah, so every order is 100% authentic and ships from the UK. | R34: vilvah hair growth oil review · vilvah hair growth oil how to use · vilvah hair growth oil benefits · vilvah hair growth oil india · vilvah hair growth oil review before and after · vilvah hair growth oil amazon | S34: Matched | T34: Review: source copy has medical-style claims (kept out of intro)
A35: VD-034 | B35: Vilvah | C35: Herbal Shampoo (Dandruff Control) | D35: Shampoo | E35: Anti-Dandruff | F35: shampoo for dandruff | G35: =IFERROR(INDEX('Semrush Data'!$C$2:$C$5000,MATCH(F35,'Semrush Data'!$A$2:$A$5000,0)),"") -> 1600 | H35: =IFERROR(INDEX('Semrush Data'!$D$2:$D$5000,MATCH(F35,'Semrush Data'!$A$2:$A$5000,0)),"") -> 31 | I35: vilvah | J35: =IFERROR(INDEX('Semrush Data'!$C$2:$C$5000,MATCH(I35,'Semrush Data'!$A$2:$A$5000,0)),"") -> 480 | K35: /collections/shampoo-for-dandruff | L35: Vilvah Herbal Shampoo (Dandruff Control) | M35: Vilvah Herbal Shampoo (Dandruff Control) | Swansura UK | N35: =LEN(M35) -> 54 | O35: Buy Vilvah Herbal Shampoo (Dandruff Control), a natural shampoo for dandruff from Vilvah. Official UK partner, 100% authentic, free UK delivery over £50. | P35: =LEN(O35) -> 153 | Q35: Vilvah Herbal Shampoo (Dandruff Control) is a natural shampoo for dandruff from Vilvah. Crafted with Neem, Tea Tree, Rosemary, and Black Pepper to effectively combat dandruff and soothe scalp irritation. Contains no parabens, sulfates, or artificial fragrances, making it a safe choice for sensitive scalps. Swansura is an official UK partner of Vilvah, so every order is 100% authentic and ships from the UK. | R35: vilvah herbal shampoo dandruff control | S35: Matched | T35: Review: source copy has medical-style claims (kept out of intro)
A36: VD-035 | B36: Vilvah | C36: Lip Balm - Grapefruit | D36: Lip Care | E36: Dry Lips | F36: lip balm for dry lips | G36: =IFERROR(INDEX('Semrush Data'!$C$2:$C$5000,MATCH(F36,'Semrush Data'!$A$2:$A$5000,0)),"") -> 1000 | H36: =IFERROR(INDEX('Semrush Data'!$D$2:$D$5000,MATCH(F36,'Semrush Data'!$A$2:$A$5000,0)),"") -> 41 | I36: vilvah | J36: =IFERROR(INDEX('Semrush Data'!$C$2:$C$5000,MATCH(I36,'Semrush Data'!$A$2:$A$5000,0)),"") -> 480 | K36: /collections/lip-balm-for-dry-lips | L36: Vilvah Lip Balm - Grapefruit | M36: Vilvah Lip Balm - Grapefruit | Lip Balm for Dry Lips | N36: =LEN(M36) -> 52 | O36: Buy Vilvah Lip Balm - Grapefruit, a natural lip balm for dry lips from Vilvah. Official UK partner: 100% authentic, shipped from the UK, free delivery over £50. | P36: =LEN(O36) -> 160 | Q36: Vilvah Lip Balm - Grapefruit is a natural lip balm for dry lips from Vilvah. Swansura is an official UK partner of Vilvah, so every order is 100% authentic and ships from the UK. | R36: vilvah lip balm grapefruit · vilvah grapefruit lip balm review · vilvah grapefruit lip balm 10g · vilvah grapefruit lip balm benefits · vilvah grapefruit lip balm amazon · vilvah lip balm review | S36: Not found – write from pack
